<mujoco model="a1_description">
    <compiler angle="radian" meshdir="/home/qyw/rl_project/legged_gym/resources/robots/a1/meshes/" />
    <size njmax="500" nconmax="100" />
    <asset>
        <mesh name="trunk" file="trunk.stl" />
        <mesh name="hip" file="hip.stl" />
        <mesh name="thigh_mirror" file="thigh_mirror.stl" />
        <mesh name="calf" file="calf.stl" />
        <mesh name="thigh" file="thigh.stl" />
    </asset>
    <worldbody>
    <body name="robot" pos="0 0 0.415" quat="1 0 0 0">
        <joint name="float_base" type="free"/>
        <inertial pos="0 0 0" quat="1 0 0 0" mass="4.713" diaginertia="0.0168 0.0566 0.0647"/> 
        <site name="imu" pos="-0.02557 0 0.04232" />

        <geom size="0.0005 0.0005 0.0005" type="box" contype="0" conaffinity="0" group="1" />
        <geom type="mesh" contype="0" conaffinity="0" group="1" rgba="0.12 0.15 0.2 1" mesh="trunk" />
        <geom size="0.1335 0.097 0.057" type="box" rgba="0.12 0.15 0.2 1" />
        <geom size="0.0005 0.0005 0.0005" type="box" contype="0" conaffinity="0" group="1" rgba="0.8 0 0 1" />

        <body name="FL_hip" pos="0.183 0.047 0">
            <inertial pos="-0.003311 0.000635 3.1e-05" quat="0.494499 0.491507 0.506268 0.507528" mass="0.696" diaginertia="0.000807752 0.00055293 0.000468983" />
            <joint name="FL_hip_joint" pos="0 0 0" axis="1 0 0" limited="true" damping="0.1" armature="0.01" frictionloss="0.2" range="-0.802851 0.802851" />
            <geom type="mesh" contype="0" conaffinity="0" group="1" rgba="0.12 0.15 0.2 1" mesh="hip" />
            <body name="FL_thigh" pos="0 0.08505 0">
                <inertial pos="-0.003237 -0.022327 -0.027326" quat="0.999125 0.00256393 -0.0409531 0.00806091" mass="1.013" diaginertia="0.00555739 0.00513936 0.00133944" />
                <joint name="FL_thigh_joint" pos="0 0 0" axis="0 1 0" limited="true" damping="0.1" armature="0.01" frictionloss="0.2" range="-1.0472 4.18879" />
                <geom type="mesh" contype="0" conaffinity="0" group="1" rgba="0.12 0.15 0.2 1" mesh="thigh" />
                <geom size="0.1 0.01225 0.017" pos="0 0 -0.1" quat="0.707107 0 0.707107 0" type="box" rgba="0.12 0.15 0.2 1" />
                <body name="FL_calf" pos="0 0 -0.2">
                    <inertial pos="0.00472659 0 -0.131975" quat="0.706886 0.017653 0.017653 0.706886" mass="0.226" diaginertia="0.00340344 0.00339393 3.54834e-05" />
                    <joint name="FL_calf_joint" pos="0 0 0" axis="0 1 0" limited="true" damping="0.1" armature="0.01" frictionloss="0.2" range="-2.69653 -0.916298" />
                    <geom type="mesh" contype="0" conaffinity="0" group="1" rgba="0.12 0.15 0.2 1" mesh="calf" />
                    <geom size="0.1 0.008 0.008" pos="0 0 -0.1" quat="0.707107 0 0.707107 0" type="box" rgba="0.12 0.15 0.2 1" />
                    <geom size="0.01" pos="0 0 -0.2" contype="0" conaffinity="0" group="1" rgba="0.12 0.15 0.2 1" />
                    <geom size="0.02" pos="0 0 -0.2" rgba="0.12 0.15 0.2 1" />
                </body>
            </body>
        </body>
        <body name="FR_hip" pos="0.183 -0.047 0">
            <inertial pos="-0.003311 -0.000635 3.1e-05" quat="0.507528 0.506268 0.491507 0.494499" mass="0.696" diaginertia="0.000807752 0.00055293 0.000468983" />
            <joint name="FR_hip_joint" pos="0 0 0" axis="1 0 0" limited="true"  damping="0.1" armature="0.01" frictionloss="0.2" range="-0.802851 0.802851" />
            <geom quat="0 1 0 0" type="mesh" contype="0" conaffinity="0" group="1" rgba="0.12 0.15 0.2 1" mesh="hip" />
            <body name="FR_thigh" pos="0 -0.08505 0">
                <inertial pos="-0.003237 0.022327 -0.027326" quat="0.999125 -0.00256393 -0.0409531 -0.00806091" mass="1.013" diaginertia="0.00555739 0.00513936 0.00133944" />
                <joint name="FR_thigh_joint" pos="0 0 0" axis="0 1 0" limited="true"  damping="0.1" armature="0.01" frictionloss="0.2" range="-1.0472 4.18879" />
                <geom type="mesh" contype="0" conaffinity="0" group="1" rgba="0.12 0.15 0.2 1" mesh="thigh_mirror" />
                <geom size="0.1 0.01225 0.017" pos="0 0 -0.1" quat="0.707107 0 0.707107 0" type="box" rgba="0.12 0.15 0.2 1" />
                <body name="FR_calf" pos="0 0 -0.2">
                    <inertial pos="0.00472659 0 -0.131975" quat="0.706886 0.017653 0.017653 0.706886" mass="0.226" diaginertia="0.00340344 0.00339393 3.54834e-05" />
                    <joint name="FR_calf_joint" pos="0 0 0" axis="0 1 0" limited="true"  damping="0.1" armature="0.01" frictionloss="0.2" range="-2.69653 -0.916298" />
                    <geom type="mesh" contype="0" conaffinity="0" group="1" rgba="0.12 0.15 0.2 1" mesh="calf" />
                    <geom size="0.1 0.008 0.008" pos="0 0 -0.1" quat="0.707107 0 0.707107 0" type="box" rgba="0.12 0.15 0.2 1" />
                    <geom size="0.01" pos="0 0 -0.2" contype="0" conaffinity="0" group="1" rgba="0.12 0.15 0.2 1" />
                    <geom size="0.02" pos="0 0 -0.2" rgba="0.12 0.15 0.2 1" />
                </body>
            </body>
        </body>
        <body name="RL_hip" pos="-0.183 0.047 0">
            <inertial pos="0.003311 0.000635 3.1e-05" quat="0.506268 0.507528 0.494499 0.491507" mass="0.696" diaginertia="0.000807752 0.00055293 0.000468983" />
            <joint name="RL_hip_joint" pos="0 0 0" axis="1 0 0" limited="true" damping="0.1" armature="0.01" frictionloss="0.2" range="-0.802851 0.802851" />
            <geom quat="0 0 1 0" type="mesh" contype="0" conaffinity="0" group="1" rgba="0.12 0.15 0.2 1" mesh="hip" />
            <body name="RL_thigh" pos="0 0.08505 0">
                <inertial pos="-0.003237 -0.022327 -0.027326" quat="0.999125 0.00256393 -0.0409531 0.00806091" mass="1.013" diaginertia="0.00555739 0.00513936 0.00133944" />
                <joint name="RL_thigh_joint" pos="0 0 0" axis="0 1 0" limited="true" damping="0.1" armature="0.01" frictionloss="0.2" range="-1.0472 4.18879" />
                <geom type="mesh" contype="0" conaffinity="0" group="1" rgba="0.12 0.15 0.2 1" mesh="thigh" />
                <geom size="0.1 0.01225 0.017" pos="0 0 -0.1" quat="0.707107 0 0.707107 0" type="box" rgba="0.12 0.15 0.2 1" />
                <body name="RL_calf" pos="0 0 -0.2">
                    <inertial pos="0.00472659 0 -0.131975" quat="0.706886 0.017653 0.017653 0.706886" mass="0.226" diaginertia="0.00340344 0.00339393 3.54834e-05" />
                    <joint name="RL_calf_joint" pos="0 0 0" axis="0 1 0" limited="true" damping="0.1" armature="0.01" frictionloss="0.2" range="-2.69653 -0.916298" />
                    <geom type="mesh" contype="0" conaffinity="0" group="1" rgba="0.12 0.15 0.2 1" mesh="calf" />
                    <geom size="0.1 0.008 0.008" pos="0 0 -0.1" quat="0.707107 0 0.707107 0" type="box" rgba="0.12 0.15 0.2 1" />
                    <geom size="0.01" pos="0 0 -0.2" contype="0" conaffinity="0" group="1" rgba="0.12 0.15 0.2 1" />
                    <geom size="0.02" pos="0 0 -0.2" rgba="0.12 0.15 0.2 1" />
                </body>
            </body>
        </body>    
        <body name="RR_hip" pos="-0.183 -0.047 0">
            <inertial pos="0.003311 -0.000635 3.1e-05" quat="0.491507 0.494499 0.507528 0.506268" mass="0.696" diaginertia="0.000807752 0.00055293 0.000468983" />
            <joint name="RR_hip_joint" pos="0 0 0" axis="1 0 0" limited="true" damping="0.1" armature="0.01" frictionloss="0.2" range="-0.802851 0.802851" />
            <geom quat="0 0 0 -1" type="mesh" contype="0" conaffinity="0" group="1" rgba="0.12 0.15 0.2 1" mesh="hip" />
            <body name="RR_thigh" pos="0 -0.08505 0">
                <inertial pos="-0.003237 0.022327 -0.027326" quat="0.999125 -0.00256393 -0.0409531 -0.00806091" mass="1.013" diaginertia="0.00555739 0.00513936 0.00133944" />
                <joint name="RR_thigh_joint" pos="0 0 0" axis="0 1 0" limited="true" damping="0.1" armature="0.01" frictionloss="0.2" range="-1.0472 4.18879" />
                <geom type="mesh" contype="0" conaffinity="0" group="1" rgba="0.12 0.15 0.2 1" mesh="thigh_mirror" />
                <geom size="0.1 0.01225 0.017" pos="0 0 -0.1" quat="0.707107 0 0.707107 0" type="box" rgba="0.12 0.15 0.2 1" />
                <body name="RR_calf" pos="0 0 -0.2">
                    <inertial pos="0.00472659 0 -0.131975" quat="0.706886 0.017653 0.017653 0.706886" mass="0.226" diaginertia="0.00340344 0.00339393 3.54834e-05" />
                    <joint name="RR_calf_joint" pos="0 0 0" axis="0 1 0" limited="true" damping="0.1" armature="0.01" frictionloss="0.2" range="-2.69653 -0.916298" />
                    <geom type="mesh" contype="0" conaffinity="0" group="1" rgba="0.12 0.15 0.2 1" mesh="calf" />
                    <geom size="0.1 0.008 0.008" pos="0 0 -0.1" quat="0.707107 0 0.707107 0" type="box" rgba="0.12 0.15 0.2 1" />
                    <geom size="0.01" pos="0 0 -0.2" contype="0" conaffinity="0" group="1" rgba="0.12 0.15 0.2 1" />
                    <geom size="0.02" pos="0 0 -0.2" rgba="0.12 0.15 0.2 1" />
                </body>
            </body>
        </body>
    </body>
    </worldbody>
        <actuator>      
        <motor name="FL_hip_joint" joint="FL_hip_joint" gear="1" ctrllimited="true"  ctrlrange="-12 12"/>
        <motor name="FL_thigh_joint" joint="FL_thigh_joint" gear="1" ctrllimited="true"  ctrlrange="-12 12"/>
        <motor name="FL_calf_joint" joint="FL_calf_joint" gear="1" ctrllimited="true"  ctrlrange="-12 12"/>
        
        <motor name="FR_hip_joint" joint="FR_hip_joint" gear="1" ctrllimited="true"  ctrlrange="-12 12"/>
        <motor name="FR_thigh_joint" joint="FR_thigh_joint" gear="1" ctrllimited="true"  ctrlrange="-12 12"/>
        <motor name="FR_calf_joint" joint="FR_calf_joint" gear="1" ctrllimited="true"  ctrlrange="-12 12"/>
        
        <motor name="RL_hip_joint" joint="RL_hip_joint" gear="1" ctrllimited="true"  ctrlrange="-12 12"/>
        <motor name="RL_thigh_joint" joint="RL_thigh_joint" gear="1" ctrllimited="true"  ctrlrange="-12 12"/>
        <motor name="RL_calf_joint" joint="RL_calf_joint" gear="1" ctrllimited="true"  ctrlrange="-12 12"/>
        
        <motor name="RR_hip_joint" joint="RR_hip_joint" gear="1" ctrllimited="true"  ctrlrange="-12 12"/>
        <motor name="RR_thigh_joint" joint="RR_thigh_joint" gear="1" ctrllimited="true" ctrlrange="-12 12"/>
        <motor name="RR_calf_joint" joint="RR_calf_joint" gear="1" ctrllimited="true" ctrlrange="-12 12"/>
    </actuator>
 <sensor>
        <actuatorpos name='FR_hip_joint_p'  actuator='FR_hip_joint' user='13'/>
        <actuatorpos name='FR_thigh_joint_p'  actuator='FR_thigh_joint' user='13'/>
        <actuatorpos name='FR_calf_joint_p'  actuator='FR_calf_joint' user='13'/>
        <actuatorpos name='FL_hip_joint_p'  actuator='FL_hip_joint' user='13'/>
        <actuatorpos name='FL_thigh_joint_p'  actuator='FL_thigh_joint' user='13'/>
        <actuatorpos name='FL_calf_joint_p'  actuator='FL_calf_joint' user='13'/>
        <actuatorpos name='RR_hip_joint_p'  actuator='RR_hip_joint' user='13'/>
        <actuatorpos name='RR_thigh_joint_p'  actuator='RR_thigh_joint' user='13'/>
        <actuatorpos name='RR_calf_joint_p'  actuator='RR_calf_joint' user='13'/>
        <actuatorpos name='RL_hip_joint_p'  actuator='RL_hip_joint' user='13'/>
        <actuatorpos name='RL_thigh_joint_p'  actuator='RL_thigh_joint' user='13'/>
        <actuatorpos name='RL_calf_joint_p'  actuator='RL_calf_joint' user='13'/>

        <actuatorvel name='FR_hip_joint_v'  actuator='FR_hip_joint' user='13'/>
        <actuatorvel name='FR_thigh_joint_v'  actuator='FR_thigh_joint' user='13'/>
        <actuatorvel name='FR_calf_joint_v'  actuator='FR_calf_joint' user='13'/>
        <actuatorvel name='FL_hip_joint_v'  actuator='FL_hip_joint' user='13'/>
        <actuatorvel name='FL_thigh_joint_v'  actuator='FL_thigh_joint' user='13'/>
        <actuatorvel name='FL_calf_joint_v'  actuator='FL_calf_joint' user='13'/>
        <actuatorvel name='RR_hip_joint_v'  actuator='RR_hip_joint' user='13'/>
        <actuatorvel name='RR_thigh_joint_v'  actuator='RR_thigh_joint' user='13'/>
        <actuatorvel name='RR_calf_joint_v'  actuator='RR_calf_joint' user='13'/>
        <actuatorvel name='RL_hip_joint_v'  actuator='RL_hip_joint' user='13'/>
        <actuatorvel name='RL_thigh_joint_v'  actuator='RL_thigh_joint' user='13'/>
        <actuatorvel name='RL_calf_joint_v'  actuator='RL_calf_joint' user='13'/>

        <actuatorfrc name='FR_hip_joint_f'  actuator='FR_hip_joint'  user='13' noise='1e-3'/>
        <actuatorfrc name='FR_thigh_joint_f'  actuator='FR_thigh_joint'  user='13' noise='1e-3'/>
        <actuatorfrc name='FR_calf_joint_f'  actuator='FR_calf_joint'  user='13' noise='1e-3'/>
        <actuatorfrc name='FL_hip_joint_f'  actuator='FL_hip_joint'  user='13' noise='1e-3'/>
        <actuatorfrc name='FL_thigh_joint_f'  actuator='FL_thigh_joint'  user='13' noise='1e-3'/>
        <actuatorfrc name='FL_calf_joint_f'  actuator='FL_calf_joint'  user='13' noise='1e-3'/>
        <actuatorfrc name='RR_hip_joint_f'  actuator='RR_hip_joint'  user='13' noise='1e-3'/>
        <actuatorfrc name='RR_thigh_joint_f'  actuator='RR_thigh_joint'  user='13' noise='1e-3'/>
        <actuatorfrc name='RR_calf_joint_f'  actuator='RR_calf_joint'  user='13' noise='1e-3'/>
        <actuatorfrc name='RL_hip_joint_f'  actuator='RL_hip_joint'  user='13' noise='1e-3'/>
        <actuatorfrc name='RL_thigh_joint_f'  actuator='RL_thigh_joint'  user='13' noise='1e-3'/>
        <actuatorfrc name='RL_calf_joint_f'  actuator='RL_calf_joint'  user='13' noise='1e-3'/>

        <framequat     name='orientation' objtype='site' noise='0.001' objname='imu'/>
        <framepos      name='position' objtype='site' noise='0.001' objname='imu'/>
        <gyro          name='angular-velocity'    site='imu' noise='0.005' cutoff='34.9'/>
        <velocimeter   name='linear-velocity'     site='imu' noise='0.001' cutoff='30'/>
        <accelerometer name='linear-acceleration' site='imu' noise='0.005' cutoff='157'/>
        <magnetometer  name='magnetometer'        site='imu'/>
    </sensor>
</mujoco>
